2020-12-08 16:35:17,232 - [test_register_case.py-->line:30] - ERROR: 注册失败-手机号为字符串执行失败
2020-12-08 16:35:17,233 - [test_register_case.py-->line:31] - ERROR: '无效的手机格式' != '账号已存在'
- 无效的手机格式
+ 账号已存在
Traceback (most recent call last):
  File "/Users/mlamp/Desktop/python/python-project/project_day20/test_case/test_register_case.py", line 27, in test_register
    self.assertEqual(expected['msg'],result['msg'])
  File "/Library/Frameworks/Python.framework/Versions/3.7/lib/python3.7/unittest/case.py", line 852, in assertEqual
    assertion_func(first, second, msg=msg)
  File "/Library/Frameworks/Python.framework/Versions/3.7/lib/python3.7/unittest/case.py", line 1233, in assertMultiLineEqual
    self.fail(self._formatMessage(msg, standardMsg))
  File "/Library/Frameworks/Python.framework/Versions/3.7/lib/python3.7/unittest/case.py", line 693, in fail
    raise self.failureException(msg)
AssertionError: '无效的手机格式' != '账号已存在'
- 无效的手机格式
+ 账号已存在

2020-12-08 16:35:18,349 - [test_register_case.py-->line:30] - ERROR: 注册失败-密码数字、字母、特殊字符组成执行失败
2020-12-08 16:35:18,349 - [test_register_case.py-->line:31] - ERROR: 0 != 2
Traceback (most recent call last):
  File "/Users/mlamp/Desktop/python/python-project/project_day20/test_case/test_register_case.py", line 26, in test_register
    self.assertEqual(expected['code'],result['code'])
  File "/Library/Frameworks/Python.framework/Versions/3.7/lib/python3.7/unittest/case.py", line 852, in assertEqual
    assertion_func(first, second, msg=msg)
  File "/Library/Frameworks/Python.framework/Versions/3.7/lib/python3.7/unittest/case.py", line 845, in _baseAssertEqual
    raise self.failureException(msg)
AssertionError: 0 != 2
2020-12-08 16:35:18,854 - [test_register_case.py-->line:30] - ERROR: 注册成功-密码长度等于8执行失败
2020-12-08 16:35:18,854 - [test_register_case.py-->line:31] - ERROR: 0 != 2
Traceback (most recent call last):
  File "/Users/mlamp/Desktop/python/python-project/project_day20/test_case/test_register_case.py", line 26, in test_register
    self.assertEqual(expected['code'],result['code'])
  File "/Library/Frameworks/Python.framework/Versions/3.7/lib/python3.7/unittest/case.py", line 852, in assertEqual
    assertion_func(first, second, msg=msg)
  File "/Library/Frameworks/Python.framework/Versions/3.7/lib/python3.7/unittest/case.py", line 845, in _baseAssertEqual
    raise self.failureException(msg)
AssertionError: 0 != 2
2020-12-08 16:35:19,183 - [test_register_case.py-->line:30] - ERROR: 注册成功-密码长度等于16执行失败
2020-12-08 16:35:19,184 - [test_register_case.py-->line:31] - ERROR: 0 != 2
Traceback (most recent call last):
  File "/Users/mlamp/Desktop/python/python-project/project_day20/test_case/test_register_case.py", line 26, in test_register
    self.assertEqual(expected['code'],result['code'])
  File "/Library/Frameworks/Python.framework/Versions/3.7/lib/python3.7/unittest/case.py", line 852, in assertEqual
    assertion_func(first, second, msg=msg)
  File "/Library/Frameworks/Python.framework/Versions/3.7/lib/python3.7/unittest/case.py", line 845, in _baseAssertEqual
    raise self.failureException(msg)
AssertionError: 0 != 2
2020-12-08 16:35:19,636 - [test_register_case.py-->line:30] - ERROR: 注册成功-类型值为1执行失败
2020-12-08 16:35:19,636 - [test_register_case.py-->line:31] - ERROR: 0 != 2
Traceback (most recent call last):
  File "/Users/mlamp/Desktop/python/python-project/project_day20/test_case/test_register_case.py", line 26, in test_register
    self.assertEqual(expected['code'],result['code'])
  File "/Library/Frameworks/Python.framework/Versions/3.7/lib/python3.7/unittest/case.py", line 852, in assertEqual
    assertion_func(first, second, msg=msg)
  File "/Library/Frameworks/Python.framework/Versions/3.7/lib/python3.7/unittest/case.py", line 845, in _baseAssertEqual
    raise self.failureException(msg)
AssertionError: 0 != 2
2020-12-08 16:35:20,002 - [test_register_case.py-->line:30] - ERROR: 注册成功-类型值为0执行失败
2020-12-08 16:35:20,002 - [test_register_case.py-->line:31] - ERROR: 0 != 2
Traceback (most recent call last):
  File "/Users/mlamp/Desktop/python/python-project/project_day20/test_case/test_register_case.py", line 26, in test_register
    self.assertEqual(expected['code'],result['code'])
  File "/Library/Frameworks/Python.framework/Versions/3.7/lib/python3.7/unittest/case.py", line 852, in assertEqual
    assertion_func(first, second, msg=msg)
  File "/Library/Frameworks/Python.framework/Versions/3.7/lib/python3.7/unittest/case.py", line 845, in _baseAssertEqual
    raise self.failureException(msg)
AssertionError: 0 != 2
2020-12-08 16:35:20,441 - [test_register_case.py-->line:30] - ERROR: 注册成功-存在注册名格式正确执行失败
2020-12-08 16:35:20,441 - [test_register_case.py-->line:31] - ERROR: 0 != 2
Traceback (most recent call last):
  File "/Users/mlamp/Desktop/python/python-project/project_day20/test_case/test_register_case.py", line 26, in test_register
    self.assertEqual(expected['code'],result['code'])
  File "/Library/Frameworks/Python.framework/Versions/3.7/lib/python3.7/unittest/case.py", line 852, in assertEqual
    assertion_func(first, second, msg=msg)
  File "/Library/Frameworks/Python.framework/Versions/3.7/lib/python3.7/unittest/case.py", line 845, in _baseAssertEqual
    raise self.failureException(msg)
AssertionError: 0 != 2
